Workbook

Sheet Form Responses 1
A1: Timestamp | B1: Nama lengkap | C1: No. HP yang terdaftar di WA | D1: Nama lengkap pasangan | E1: No. HP pasangan yang terdaftar di WA | F1: Alamat domisili | G1: Alamat pengiriman | H1: Pengiriman | I1: Durasi sewa | J1: Unit yang akan disewa | K1: Username Instagram | L1: Follow instagram @sewasamamira | M1: Foto KTP suami | N1: Bukti transfer deposit | O1: Foto KTP istri | P1: Foto KTP suami dan istri | Q1: Column 17
A2: 45786.741 | B2: Irma khairunnisa | C2: 089601661537 | D2: Dicka nirwansyah | E2: 081324366585 | F2: jl madrasah 1 rt 26 rw 03 gandul | G2: jl madrasah 1 rt 26 rw 03 gandul | H2: Shopee | I2: 7 hari | J2: spectra dual compact | K2: irmakhnisa
A3: 45790.531 | B3: Nadya Wulandari Rahmadi | C3: 082295284178 | D3: Febryci Legirian | E3: +628117137420 | F3: Suvarna Sutera Cluster Dakota 16 No. 50 Kec. Sindang Jaya Kab. Tangerang Prov. Banten 15560 | G3: Suvarna Sutera Cluster Dakota 16 No. 50 Kec. Sindang Jaya Kab. Tangerang Prov. Banten 15560 | H3: Shopee | I3: 7 hari | J3: Gabag Maximo | K3: ayinshabrina | L3: https://drive.google.com/open?id=1WUwSgwIE-UB3ttSb9WvRnCg6qTnHMMIq | M3: https://drive.google.com/open?id=1cGbzaZh4OOVOwt9dHwX-evhkZm2bHVd7 | N3: https://drive.google.com/open?id=1LeNETdX8-VHkD16maD3SelFRImXKgzkM
A4: 45791.599 | B4: Susan suwuwaty | C4: 082211883368 | D4: Rommy Tandradynata | E4: 08111816809 | F4: Jl bsd sektor I no 66 | G4: Anggrek loka sektor 2.1 blok i no 12 | H4: Shopee | I4: 7 hari | J4: Unit baru momabae compact s+ | K4: Sansan_shu | L4: https://drive.google.com/open?id=1LSUncHpZSKUqB1iF30KOvTy0WqOZM9MY | M4: https://drive.google.com/open?id=1fTpG2A2v3S4CdYDwlB9-CXnl2Pniau9b, https://drive.google.com/open?id=150ErVuDNsI85oIzhI8bNEfBdFRxM_fwF | N4: https://drive.google.com/open?id=1b_z47WzwoJ6iZxSXgug7AAsmn4vvg-eF
A5: 45795.428 | B5: Devi Apriani | C5: 08121478760 | D5: Reuben Komala | E5: 081311447700 | F5: The Casilla Townhouse, unit B. Jl. Cilandak Dalam no. 22, Cilandak Barat, Jakarta Selatan | G5: The Casilla Townhouse, unit B. Jl. Cilandak Dalam no. 22, Cilandak Barat, Jakarta Selatan | H5: Luar shopee (JNE/Instant (order sendiri)/Same day (order sendiri) | I5: 7 hari | J5: Nevia milk warmer | K5: @isobelolita | L5: https://drive.google.com/open?id=1gA2yokVq4VuAf1ya0s60k6zqse7iLEOV | M5: https://drive.google.com/open?id=1UJgSVEDeDtLJO4KqA-DSqvQrSuoFx3nn | N5: https://drive.google.com/open?id=1ZZsfNApD30qXXfLhZ8N3wDKumGvR-fjW
A6: 45795.435 | B6: Mayang Gita Tamara | C6: 085768062295 | D6: Aji gustoponi | E6: +62 812-7778-0275 | F6: Cluster taman palem merah 6a | G6: Cluster taman palem merah 6a no 6 | H6: Shopee | I6: 7 hari | J6: Spectra dual compact | K6: Mayanggitatamara | M6: https://drive.google.com/open?id=1f4FTqpwuXut4Flv7Mwp--FU8ejF_UiLl | N6: https://drive.google.com/open?id=1gxRwqS3ghNp5nrj4devn3Nc6cdZHd5a3
A7: 45797.595 | B7: Erlita Triandini Pratiwi | C7: 081291810124 | D7: Erfikhar Fadhlurrahman | E7: +62 812-9862-3199 | F7: Binong Permai B-11/11 RT 04 RW 12 Kec. Curug Kel. Binong Kab.Tangerang | G7: Griya Muda (Jl. Inspeksi 2 No.1, RT.004/RW.005, Kunciran Indah, Kec. Pinang, Kota Tangerang, Banten 15144) Lantai 2 no B.2.1 | H7: Luar shopee (JNE/Instant (order sendiri)/Same day (order sendiri) | I7: 7 hari | J7: Spectra 9+ & Mom uung handsfree | K7: erltripr | L7: https://drive.google.com/open?id=1BQbdfzKOO_T1CEZESBpH9kUWCt-zsT2Q | M7: https://drive.google.com/open?id=1R8uuPoss1CttS0CV9L9tydsjGtyMhgkI | N7: https://drive.google.com/open?id=1y6HVHepgRdF4jGoGbXw7uZmjKPikTcpJ
A8: 45797.81 | B8: Mahardiani Beningrum | C8: 081287615055 | D8: Lincah Wahyono | E8: +62 812-9015-4205 | F8: Bukit Serpong Mas Blok D5 No 5 Jl. Raya Serpong Kilometer 7, Pakulonan, Kec. Serpong Utara, Kota Tangerang Selatan, Banten 15325 | G8: Bukit Serpong Mas Blok D5 No 5 Jl. Raya Serpong Kilometer 7, Pakulonan, Kec. Serpong Utara, Kota Tangerang Selatan, Banten 15325 | H8: Luar shopee (JNE/Instant (order sendiri)/Same day (order sendiri) | I8: 7 hari | J8: Momabae handsfree | K8: @dianbening74 | M8: https://drive.google.com/open?id=17AC54joHrskWGPPHeZhtE_gys-_kAJll | N8: https://drive.google.com/open?id=1gAQhsiEu5z5k5_cJ_Uf1yyMRwYS40aSY
A9: 45799.739 | B9: Gita | C9: 081211054211 | D9: Putra | E9: 081802535816 | F9: Jl. Syafiul Ikhwan RT 07/ RW 02 No 18A Jaticempaka, Pondok Gede, Bekasi | G9: Jl. Syafiul Ikhwan RT 07/ RW 02 No 18A Jaticempaka, Pondok Gede, Bekasi | H9: Shopee | I9: 7 hari | J9: Spectra dual compact | K9: @gitaavana | L9: https://drive.google.com/open?id=1cTE7q0UYRWyYatpjsFYZLGiL0SPQ2Cie | M9: https://drive.google.com/open?id=10PzLpJeQIPDTyKSWEX9LGulpht_c3N7i | N9: https://drive.google.com/open?id=17TbdsAxdC99tZ9vNeC4K1rZbDOoj90el
A10: 45799.882 | B10: Arnila julianti frahatini | C10: 089681478738 | D10: Wahyu hidayat | E10: +62 896-3848-8355 | F10: Karawaci, kota tangerang | G10: Jl. Pesantren 1 no.20 kel. Pabuaran, karawaci kota tangerang | H10: Shopee | I10: 7 hari | J10: Momabae omni | K10: arnilajf_ | L10: https://drive.google.com/open?id=1U4oeqvk1XkB65lH3Y8qq31muQ4ywCgQD | M10: https://drive.google.com/open?id=1gaIxrN1qXP40-jsFIzoSBfudyb7bBmOg | N10: https://drive.google.com/open?id=1TnlOhvylF7q39Uo_O6YtICB_GlFy6m7s
A11: 45803.572 | B11: Tika Dwi Astuti | C11: 085717924576 | D11: Eko Akhsanul Fikri | E11: +62 878-7190-0815 | F11: Jl. H. Kayar No. 36 RT 9/RW 6, Kel. Ciganjur, Kec. Jagakarsa, Jakarta Selatan | G11: Tika Dwi A (Kontrakan Umi Sur sebelah warung Bude Emi) Jl. H. Kayar No. 36 RT 9/RW 6, Kel. Ciganjur, Kec. Jagakarsa, Jakarta Selatan 12630 | H11: Luar shopee (JNE/Instant (order sendiri)/Same day (order sendiri) | I11: 14 hari | J11: Gabag I-Max Pro LED | K11: ticapricorn24 | L11: https://drive.google.com/open?id=1eNhBy16BhSnJr2uP0a7m9ZzJRcvwsqMM | M11: https://drive.google.com/open?id=1cIJU1GJF50XpSLD2IqDaXgHOrBYnpRJp, https://drive.google.com/open?id=1qb4PITcTZUH5C8JUPoupjWtxwe2D6aRf | N11: https://drive.google.com/open?id=1NSvhiOoZV-cUKBCidm19ChWbrinZvV5W
A12: 45805.577 | B12: Esa safitri | C12: 085828165137 | D12: Arpan | E12: 087840633411 | F12: Jl kh syahdan no 19A kelurahan palmerah kecamatan palmerah | G12: Jl kh syahdan no 19A kelurahan palmerah kecamatan palmerah 11480 | H12: Shopee | I12: 30 hari | J12: Pompa spectra 9+ | K12: Esasftr | L12: https://drive.google.com/open?id=199I7nSvN5Uvu0pbpZhrKEq8HL53me0CL | M12: https://drive.google.com/open?id=1L2tJOqcpRSO31Ztj1fks9F4XGwE9yzVf | N12: https://drive.google.com/open?id=1FSV4yMv-IyNkxDhrzAFlrtj9aom4E--K
A13: 45808.502 | B13: Ayuni Purnamasari | C13: 085966778989 | D13: Hanly Aries B | E13: 081977777009 | F13: Menaggio Barat 3 no.33 Curug Sangereng, Kelapa Dua, Kab. Tangerang | G13: Menaggio Barat 3 no. 33 Curug Sangereng, Kelapa Dua, Kab. Tangerang. 15810 | H13: Luar shopee (JNE/Instant (order sendiri)/Same day (order sendiri) | I13: 14 hari | J13: Momabae Omni | K13: Ochibi89 | L13: https://drive.google.com/open?id=1e2BxLF6nGo2Yo2SGVDIL9kJbmbLDdnyI | M13: https://drive.google.com/open?id=1A7AbaIwi59x_KLbnmbXk5pfvI6jDyfCh, https://drive.google.com/open?id=1i3cvb-fD_jj_--4aqVAtro0Sw-gGlYI2 | N13: https://drive.google.com/open?id=1yc0QJQdqDOKU5R_gpFntnF-5PZ-wSf0T
A14: 45808.523 | B14: Nova Yunita Sari | C14: 087771661914 | D14: Suherli | E14: +6289651079786 | F14: Perum kiara rahayu blok G1 no.4 walantaka serang-banten (belakang SMA ciruas) | G14: Perum kiara rahayu blok G1 no.27 walantaka serang-banten (belakang SMA ciruas) | H14: Shopee | I14: 14 hari | J14: POMPA ASI HANDFREE MOM UUNG | K14: Nova.yunsar | L14: https://drive.google.com/open?id=137Wv8WjKHPZA5N6s1U5-3Kg0U2kpxypE | M14: https://drive.google.com/open?id=1rNNngu_MEXndPoUJk2f5JSgfAzCdlTHB, https://drive.google.com/open?id=1qKdciVK6azPgVADhFvHCu0U5AC8xqcjc | N14: https://drive.google.com/open?id=1VrVVnTbcy3ZZonXfWc3E6MrePLErcGGc
A15: 45808.568 | B15: Titik Puspitasari | C15: 087734924514 | D15: Bahri Wahabi | E15: 082112442047 | F15: Villa Mutiara Pluit Blok F 10 no 19 RT 06 RW 09, Periuk, Kota Tangerang | G15: Villa Mutiara Pluit Blok F 10 no 19 RT 06 RW 09, Periuk, Kota Tangerang | H15: Luar shopee (JNE/Instant (order sendiri)/Same day (order sendiri) | I15: 14 hari | J15: Spectra dual compact | K15: tpuspita | L15: https://drive.google.com/open?id=17skqk6azwTQgse1qyIZff9qBG6IIHs-G | M15: https://drive.google.com/open?id=1hFl2xFeqUwa0uhK7GVtyF8Bf6X2AdiRE | N15: https://drive.google.com/open?id=19WOBwrkTQBCRc7MFaQqrLqIFJOHT2tQC | O15: https://drive.google.com/open?id=1-iY0wgl5ct7oJlZw3ajydbNn5zzTdq36
A16: 45811.664 | B16: Monica | C16: 087781754903 | D16: Kevin Andrew | E16: 081901231188 | F16: Apartemen Mediterania Marina | G16: Apartment Aston Marina Ancol, Jalan Lodan Raya Blok B, RT.8/RW.11, Ancol, Tanjung Priok (Tower C / 09 / BG), KOTA JAKARTA UTARA, TANJUNG PRIOK, DKI JAKARTA, ID, 14350 | H16: Shopee | I16: 7 hari | J16: Gabag Maximo | K16: louisacinom | L16: https://drive.google.com/open?id=1olFAOFPCt_IVmWdiO2Hx6BAeHVNdng5d | M16: https://drive.google.com/open?id=1dd8YMpNZLO2cujfJdn9KeMjugkkh74ee | N16: https://drive.google.com/open?id=1_-A5a02TqrvZBzrC4TrcHlORf_VB4v-o | O16: https://drive.google.com/open?id=18hYvYW_AmJ2ZM6RblhtHiNlbP3HwChdS
A17: 45813.314 | B17: Habibatuz Zuhriyah | C17: 085173220597 | D17: Hari Fajar Apriyanto | E17: 082298269527 | F17: Jl. Bandeng III, No. 106a, RT/RW 007/009, Kel. Karawaci Baru, Kec. Karawaci, Kota Tangerang | G17: Jl. Bandeng III, No. 106a, RT/RW 007/009, Kel. Karawaci Baru, Kec. Karawaci, Kota Tangerang | H17: Shopee | I17: 30 hari | J17: Pompa ASI Gabag Maximo | K17: @rifajarap | L17: https://drive.google.com/open?id=1sOahDj4s6I1VsDtmXGnYAwy3norlF0JF | M17: https://drive.google.com/open?id=10PhfSWOIvmrJ0s58rM5JJH5B3OLtmth5 | N17: https://drive.google.com/open?id=1fSl6He8j0oeYNRHnW3qjPEC0RyEBTxY1 | O17: https://drive.google.com/open?id=1gowrVq3Om19E-q2-jqvSB99oFaYK-9xq
A18: 45813.495 | B18: Agnes Christyati | C18: 082213798220 | D18: Yudhi Raharjo | E18: 081389969922 | F18: mutiara panongan 2 tahap 2 blok bb1no.38, serdang kulon, panongan, kab tangerang | G18: mutiara panongan 2 tahap 2 blok bb1 no.38, serdang kulon, panongan, kab tangerang | H18: Shopee | I18: 30 hari | J18: momabae omni | K18: @agneschrstyt | L18: https://drive.google.com/open?id=1Zsax98VoMTAMWRr0wkUBc_tLAg35q0fA | M18: https://drive.google.com/open?id=19hDJMYEM6fICnLtBie-CXrRAwJnDRy-p | N18: https://drive.google.com/open?id=1rgb19xltYgg416lawh0oZ2Wqk4ST8bo_ | O18: https://drive.google.com/open?id=1gTT0RsNBBZn6XUyJyoyxmu3-95bHy1Tp
A19: 45819.396 | B19: Nurul Rahma | C19: 082226286167 | D19: Nandi agung | E19: 082198933309 | F19: Cluster graha buana blok A1 RT 03 RW 14 larangan selatan kota Tangerang | G19: Cipondoh | H19: Shopee | I19: 30 hari | J19: Gabag maximo | K19: Nurul_rahmaaa | L19: https://drive.google.com/open?id=1MdQF7mIvGGruRU5si6pxj2sfzDXlur8D | M19: https://drive.google.com/open?id=17zNbxEaMc4x4034mzsAJlUO0RcluzSwd | N19: https://drive.google.com/open?id=1yz7soltM4D57ehA98Zz9aeVoaWn4Tyba | O19: https://drive.google.com/open?id=1zmsfDs6Rt7lPVCuQxOEEKiXIKsyMHa_y
A20: 45821.65 | B20: Farida Norma Yulia | C20: 081232244405 | D20: Faris Hamidi | E20: 087885293737 | F20: https://goo.gl/maps/9Ckvxk67MUkcVXPG7 Jl. Gr B. Utara X Blok GR8 No.49, Pd. Kacang Bar., Kec. Pd. Aren, Kota Tangerang Selatan, Banten 15226 | G20: https://goo.gl/maps/9Ckvxk67MUkcVXPG7 Jl. Gr B. Utara X Blok GR8 No.49, Pd. Kacang Bar., Kec. Pd. Aren, Kota Tangerang Selatan, Banten 15226 | H20: Shopee | I20: 7 hari | J20: Bebetons Neo | K20: @ridanorma | M20: https://drive.google.com/open?id=1ciuv6oA9s780N3lxU3oo15V3sOBnubxE | N20: https://drive.google.com/open?id=1pBxuoUL_IMBULj8rzFeyWLG8rxvCVHu_ | O20: https://drive.google.com/open?id=19FUGLQIAvVpR4GiLCDcQDkv_4xl3KAip
A21: 45825.809 | B21: Christina Hariyanti | C21: 081911304300 | D21: Hans Kristian | E21: 081946891881 | F21: Villa melati mas | G21: Villa melati mas | H21: Luar shopee (JNE/Instant (order sendiri)/Same day (order sendiri) | I21: 7 hari | J21: Pompa Gabag maximo | K21: chchch.chc | L21: https://drive.google.com/open?id=1uduwCDW1RCCYcYHoQquSjs1cUFY3eb5a | M21: https://drive.google.com/open?id=1M7XcaR2SuTFSbXDc6czJ-_lts62CKRCn | N21: https://drive.google.com/open?id=1gRqK3_nqaMT-beqadx2VNzqFBVKH1Yev | O21: https://drive.google.com/open?id=1-w4aoEOQMa_PsjhgZmoNy5k5XkHFXxt5
A22: 45827.559 | B22: Rizki Widya Herawati | C22: 081218994062 | D22: Raihan Mahendra Duta | E22: +62 855-9116-8367 | F22: Pasar Lama Serpong RT013/005 no.25 Cilenggang, serpong, Tangerang Selatan | G22: PT Indotech Karya Mandiri, green lake city rukan crown blok M no.17 tangerang | H22: Luar shopee (JNE/Instant (order sendiri)/Same day (order sendiri) | I22: 7 hari | J22: Gabag imax pro cup led | K22: Rissrizki | L22: https://drive.google.com/open?id=1LguCCx-0dy6vXa03UgQNtVX80dgHmr6Q | M22: https://drive.google.com/open?id=1bcdyguk1p-Rf1cXYt8fQW8osZarxZH7h | N22: https://drive.google.com/open?id=1UhusJYu5mZ6JCqkxhWIZbNO1yN_1z5gp | O22: https://drive.google.com/open?id=1jt8pOcl-NyqEoF0FdqEXTj0IehAi9o2n
A23: 45828.551 | B23: Jihaan Jullanaar Mazaya | C23: 085314901070 | D23: Mulia Ramdhan Fauzani | E23: +62 812-1841-8424 | F23: Perumahan Soditan Permai Gang Salak Blok D13 Ngadirejo, Sukoharjo, Kartasura, Jateng 57161 | G23: Perumahan Soditan Permai Gang Salak Blok D13 Ngadirejo, Sukoharjo, Kartasura, Jateng 57161 | H23: Shopee | I23: 14 hari | J23: Spectra dual compact | K23: jijullanar | L23: https://drive.google.com/open?id=1GUqS90VO33yKY7SoLLk5EuL_6xYapCFZ | M23: https://drive.google.com/open?id=1ojGkflwyC6s5s-wmEk1EY0bSTe9Xx8R0 | N23: https://drive.google.com/open?id=1gB0fM2_KZ4TAdnXUhvPBI5PXbOOzdTcl | O23: https://drive.google.com/open?id=1DP9mMLDxArjMYD65gPgkVd7fvy3S_JEO
A24: 45833.493 | B24: Novita Zulfadesi | C24: 085363834217 | D24: Walid Bimantoro Ray | E24: +62 858-1476-5636 | F24: Perumahan Pesona Lebak Wangi 2, Jalan Kelengkeng Blok C3 No. 24, RT.2/RW.10, Lebak Wangi, Sepatan, Kab. Tangerang, Banten | G24: Perumahan Pesona Lebak Wangi 2, Jalan Kelengkeng Blok C3 No. 24, RT.2/RW.10, Lebak Wangi, Sepatan, Kab. Tangerang, Banten | H24: Shopee | I24: 30 hari | J24: Pompa Asi Portable Mom Uung | K24: nvt.zlfds | L24: https://drive.google.com/open?id=1CWCTdMdavd9I0KocfsVcBYs_jx5eDDwQ | M24: https://drive.google.com/open?id=1f9sjQ8zy529Ug0TOubNIc7rFth_DlNKu | N24: https://drive.google.com/open?id=1lrw_IwRUXGnfvvp5aMuCDqIT1wYOU7nl | O24: https://drive.google.com/open?id=18jtfIRNMm24m_BUd8XNhDbhr6Cb1f_vi
A25: 45835.499 | B25: dini privea | C25: 08161924259 | D25: wahyu H | E25: +62 813-1552-8897 | F25: Discovery Aluvia Blok S No. 8, Bintaro Tangerang Selatan (belakang driving range golf bintaro) | G25: Discovery Aluvia Blok S No. 8, Bintaro Tangerang Selatan (belakang driving range golf bintaro) | H25: Luar shopee (JNE/Instant (order sendiri)/Same day (order sendiri) | I25: 14 hari | J25: Spectra H1 handsfree | K25: @dinipriveap | L25: https://drive.google.com/open?id=1NWkQAxp-f3UUAvwFOIn9THfHzMWWAiAu | M25: https://drive.google.com/open?id=1WlPFO2HUGr-GH2GLgcpyJEISob-Bjy4I | N25: https://drive.google.com/open?id=1j16Grytb3ksMT9gz_bSOXVywSXAlAdBL | O25: https://drive.google.com/open?id=18ajkGBkjSxDQeFxTPQtlJVxqaBrkf7SX
A26: 45839.95 | B26: Diajeng Ramadawati | C26: 08818099981 | D26: Gigih Prasetyo | E26: 085171533927 | F26: Jl. Damai No. 44b Rt. 15/rw. 2, Petukangan Selatan, Pesanggrahan, Kota Jakarta Selatan, DKI Jakarta, Indonesia, 12270 | G26: Jl. Damai No. 44b Rt. 15/rw. 2, Petukangan Selatan, Pesanggrahan, Kota Jakarta Selatan, DKI Jakarta, Indonesia, 12270 | H26: Shopee | I26: 7 hari | J26: Momabae compact S+ | K26: @diajengrmdwt | L26: https://drive.google.com/open?id=1hb7RfKeY2LoVfMcyU8LauB3fQi1kwVDC | M26: https://drive.google.com/open?id=1X_FFcS5DKneWwd1zwRvr7VsfZr2NF3rm | N26: https://drive.google.com/open?id=1YdpWwe8k9UDtsOCdLEg-3iGt0Hz7tZBS | O26: https://drive.google.com/open?id=1qBJrcesml0aCqZHnaCrk9cqI87NYf2wP
A27: 45840.416 | B27: Farrah Alizah | C27: 081294166544 | D27: Muhammad Hafizhul Arief | E27: +62 812-8864-6411 | F27: Jakarta | G27: Komplek Masnaga Blok D No 12 RT 016 / RW 003 Kel. Pulogebang Kec. Cakung Jakarta Timur 13950 | H27: Shopee | I27: 7 hari | J27: Gabag Imax Pro Cup | K27: byetoxicx | L27: https://drive.google.com/open?id=1wqBjB6ZH-5SLQwY7n2JijW1iQSdLBTkT | M27: https://drive.google.com/open?id=12meRA3WRTIdDHjqz9EAcZ51jyQMAuqar | N27: https://drive.google.com/open?id=1MbQNjdzWX4BOjx6mwumfs3Dh3Zhc9tNq | O27: https://drive.google.com/open?id=1awJcvUtz91TCGfUbl_vXhh5ObyCb_aCx
A28: 45840.627 | B28: Nur Qori’ah | C28: 085784573719 | D28: Ivan Dwi Santoso | E28: 081217076500 | F28: Jl Kh Thosin No 45A RT 003 RW 005 Kel. Sudimara Selatan, Kec. Ciledug, Tangerang 15151 | G28: Jl Kh Thosin No 45A RT 003 RW 005 Kel. Sudimara Selatan, Kec. Ciledug, Tangerang 15151 | H28: Shopee | I28: 7 hari | J28: Spectra 9+ | K28: qorinsane | L28: https://drive.google.com/open?id=1L0SR69eskL1kftA8cbAyFgIqxmV1AUD_ | M28: https://drive.google.com/open?id=1L68XAyig4n91bmtnGlJoVRs-XJ1ZH4E6 | N28: https://drive.google.com/open?id=1CYfQn8sYF6opS_YhTrblQGgjckGoWurW | O28: https://drive.google.com/open?id=1sXOsMQQKB5HMvUOPAOuD8eBpnuP19dgN
A29: 45843.557 | B29: Nurbani Syifa | C29: 085718526011 | D29: Indra Permana Putra | E29: +62 895-0870-8388 | F29: Pintu air no 22c Jakarta Pusat | G29: Terminal 2F Bandara Soekarno Hatta | H29: Luar shopee (JNE/Instant (order sendiri)/Same day (order sendiri) | I29: 7 hari | J29: Gabag Maximo | K29: @nurbanisyifa | L29: https://drive.google.com/open?id=1fePvAccdF2YijAUH56FigJ-U7hrSLrme | M29: https://drive.google.com/open?id=1gq7bY_g1fzyr3jWlImBEJHVbj-jJ3iKw | N29: https://drive.google.com/open?id=1y8p2VHW1_mxMLXMqMwBEN4ho_dLiI_Pt | O29: https://drive.google.com/open?id=1hI5KB8rh2jambA0pg4r2zPc0PQMYqKsM
A30: 45849.36 | B30: Widyastuti | C30: 081328752515 | D30: Stefanus yuda pratama | E30: 081382295962 | F30: Perumahan bumi satria kencana.Jl arjuna 3 no 10 rt 6 rw 21 kelurahan kayuringin jaya kecamayan bekasi selatan.kota bekasi,jawa barat | G30: Perumahan bumi satria kencana.Jl arjuna 3 no 10 rt 6 rw 21 kelurahan kayuringin jaya kecamayan bekasi selatan.kota bekasi,jawa barat | H30: Shopee | I30: 7 hari | J30: Momabae compact S | K30: Pungky_widyastuti | L30: https://drive.google.com/open?id=1VqFggbu6SamXgHLY6wYBaQkqIYrlwQuk | M30: https://drive.google.com/open?id=1x1D-Zi4eScM5RoP71AIwKLvcpu3CcOsE | N30: https://drive.google.com/open?id=1LOFgYLu9TbXZPN2tYKE2KzDeuKK8YoG3 | O30: https://drive.google.com/open?id=112Q59AgCBG1Vi1dyEsVpxiEqnRbKVAeS
A31: 45853.062 | B31: Intan fajriyanti | C31: 081226415566 | D31: Dani suharto | E31: 081226415522 | F31: Jl kenconowungu III/24 karangay semarang barat kota semarang | G31: Jl kenconowungu III/24 karangay semarang barat kota semarang | H31: Shopee | I31: 14 hari | J31: Mommabae omnie | K31: Intanfajriyabti | L31: https://drive.google.com/open?id=1Q3uiUFRQVXTDBZH_R64ZQchf-6bs99Tu | M31: https://drive.google.com/open?id=1ljMQ1tjk8QUKCixpsXPg8KdtrpHDv3V_ | N31: https://drive.google.com/open?id=1oP9H0CHG50_XodXbZa6rEm4uiiegyZVO | O31: https://drive.google.com/open?id=1HWodmuhw815R8uBYEfrxaIhqYvGask1R
A32: 45853.496 | B32: Ayu Titik Triwahyuni | C32: 087885340951 | D32: Theodore Christopher | E32: 082123823181 | F32: Myza Cozmo Blok F 3 No. 1 | G32: Myza Cozmo Blok F 3 No. 1 | H32: Shopee | I32: 7 hari | J32: Momabae | K32: Nonnaayu | L32: https://drive.google.com/open?id=1srHUF3jfZEGatcHlRvLKTqDzHy78Qdwh | M32: https://drive.google.com/open?id=1NXo02vXUcZc4ORenzmGj0_SY7L13vC-R | N32: https://drive.google.com/open?id=1wIUE5gn9ORImx7U9wYppdTWdxvVmNM9b | O32: https://drive.google.com/open?id=15W-IXej7rWM4NIs7andZkBRQTGT0UiJ5
A33: 45854.704 | B33: Putri Nurafifah | C33: 085781241222 | D33: Muhamad Hakim | E33: 085781241222 | F33: Jl H Ilyas No 86 Lebak Bulus, Cilandak, Jaksel | G33: Jl H Ilyas No 86 Lebak Bulus, Cilandak, Jaksel | H33: Shopee | I33: 7 hari | J33: Spectra H1 dan Omni Momabae | K33: @putrinurafifah | M33: https://drive.google.com/open?id=1WT_7UMU5SVpKLdU_rj1fJaVuDLJ8nO-A | N33: https://drive.google.com/open?id=1_tFOuy0ilQMuDjJvfgCDAJOpO8jFUjYa | O33: https://drive.google.com/open?id=1vovd8SS-hhx3yYuhwi0c2FdOhgmclHRi
A34: 45857.737 | B34: rizky yuliani | C34: 085349154900 | D34: Dody handayani | E34: 082298454446 | F34: Jl kh hasyim ashari no 1 pinang tangerang | G34: Jl kh hasyim ashari no 1 pinang tangerang | H34: Shopee | I34: 14 hari | J34: Spectra 9 plus | K34: Dhedeee | M34: https://drive.google.com/open?id=1mfLCCYqpHzIRwgWvPV8PVayjPYMYLF9d | N34: https://drive.google.com/open?id=1Lwow6zzVgnXnvV7xypOCZzDwXX-DVlC_ | O34: https://drive.google.com/open?id=15NTIYg96mqQf6AHgrOB_KAPr28wDkeEC
A35: 45863.414 | B35: Elok Nur Fauziyah | C35: 085853982429 | D35: Muhammad Dwifajar Sholeh | E35: 082332572026 | F35: Jl. Udayana No.57, Trawas, Mojokerto, Jawa Timur, 61375 | G35: Jl. Udayana No.57 Rt.11/Rw.05 Ds. Tamiajeng, Kec. Trawas, Kab. Mojokerto, 61375 | H35: Shopee | I35: 7 hari | J35: Spectra dual compact, momabae compact | K35: eloknurfauziyah | L35: https://drive.google.com/open?id=1zHkLe_AmYrBzBPxKHg8gHrrhCgXAjtOc | M35: https://drive.google.com/open?id=1LISqHlabNGtD_EDQ4s0Og5p4i-QmEF51 | N35: https://drive.google.com/open?id=1Y8_a09VwD4nQarhFCryaGL5_wT2uQYX2 | O35: https://drive.google.com/open?id=1U6gcZ8eUyxxLnm6nAc6odqcrSZ3RT-IF
A36: 45863.474 | B36: Juli | C36: 087788990656 | D36: Vic | E36: 085863231888 | F36: Sunter karya selatan 6 blok b2 21 | G36: Sama domisili | H36: Shopee | I36: 30 hari | J36: Dual s spectra | K36: Juli.fransisca | M36: https://drive.google.com/open?id=17iXIqVMPCigCRHsAgpkwv9UswGuGCfKx | N36: https://drive.google.com/open?id=1crujjpmv_vBulr7-NIgB2O6mIvPvzCmv | O36: https://drive.google.com/open?id=1NaaQek2MhlNt9rb4GWBpsNcBqFR_NTHf
A37: 45867.808 | B37: Shafira Rizki Ramdhayani | C37: 081292485452 | D37: M. Billy Darisma | E37: 082279818939 | F37: Apartemen Puri Mansion, Tower Amethyst Unit TA-06L2, Kelurahan Duri Kosambi, Kecamatan Cengkareng, Jakarta Barat | G37: Apartemen Puri Mansion, Tower Amethyst Unit TA-06L2, Kelurahan Duri Kosambi, Kecamatan Cengkareng, Jakarta Barat | H37: Shopee | I37: 14 hari | J37: Spectra Dual Compact | K37: shafirarizkir | L37: https://drive.google.com/open?id=1VJ2hBRlRTVKIZXLkkS9cQUxASKgOWXPH | M37: https://drive.google.com/open?id=1dUNsRiZxXkGEG7AMDbm4EHzYSqGm3eFf | N37: https://drive.google.com/open?id=16hVN63QK_irbfxatBjWerADO-RIfsyu7 | O37: https://drive.google.com/open?id=1BEZUTcGEOf2Ovhg_3OSuhb7AyFEql7m4
A38: 45872.53 | B38: Wanda Astuti Dirmansyah | C38: 081288047493 | D38: Wisnu Kurniawan | E38: +62895380431263 | F38: Jakarta Timur | G38: Jl Manunggal XVII No.17 RT04/11, Lubang Buaya, Cipayung, Jaktim | H38: Shopee | I38: 30 hari | J38: Momabae Omni | K38: Wandasd | L38: https://drive.google.com/open?id=15ho9IXNbDLv7GxUL8c37ueMqQxNq71Dw | M38: https://drive.google.com/open?id=1zGBOK0A9lg3aEZk5rfQrizUSJQXuJ80z | N38: https://drive.google.com/open?id=1yMtSElqmULkYQxdk0vtcEnqxABUae18o | O38: https://drive.google.com/open?id=16Oon5XO1cMO6ppcygECi1MZNWsG-0UvC | R38: Booking untuk 20 agst
A39: 45873.423 | B39: Nina Darista | C39: 089668982107 | D39: Muhammad galih permana | E39: 087831469115 | F39: Cluster pesona legok blok e no 18 | G39: Rsia pratiwi tangerang | H39: Luar shopee (JNE/Instant (order sendiri)/Same day (order sendiri) | I39: 7 hari | J39: Momabae omni | K39: Naysynder | M39: https://drive.google.com/open?id=1yFq2BaH66yV4TRbtnjrvDzA-MtqKVfHs | N39: https://drive.google.com/open?id=1C8tc70FTFBpfrKcGu4Cu78N3JUvr-iZP | O39: https://drive.google.com/open?id=1ttIRSbGOlbaQN0BemdBGHtjmYe8iVvym
A40: 45873.497 | B40: Khuzaimah | C40: 081210838843 | D40: Muhammad idrus | E40: 087808559430 | F40: Jl h mencong gang saji 1 no 20 rt 001/010 ciledug tangerang | G40: IDEM | H40: Luar shopee (JNE/Instant (order sendiri)/Same day (order sendiri) | I40: 30 hari | J40: omni mommabae | K40: Khuzaimah zema | M40: https://drive.google.com/open?id=1PCOTU2VgA8YaeKJTT4F1KxcbMOrp0DCs | N40: https://drive.google.com/open?id=1AaDV_HXOyWP_kyPSwthI2CQgezQk3obJ | O40: https://drive.google.com/open?id=1KXzmZ1deggOxOSPPeX02QayjNF63kZlg
...

Sheet Stocklist
A1: 1 | B1: Spectra Dual Compact 1 | C1: In | D1: preloved tahun 2021 | E1: Back 4 maret
A2: 2 | B2: Spectra Dual Compact 2 | C2: Out | D2: preloved tahun 2022
A3: 3 | B3: Mom Uung Corong | C3: Out
A4: 4 | B4: Gabag Maximo 1 | C4: In | D4: Preloved 2023 | E4: Back 26 maret
A5: 5 | B5: Gabag Maximo 2 | C5: In | D5: Preloved 2023
A6: 6 | B6: Spectra S1+ | C6: Out | D6: Beli di pameran 2024 | E6: 46102
A7: 7 | B7: Gabag Imax Pro Cup LED | C7: In | D7: Pameran 2024
A8: 8 | B8: Malish Flexigo | C8: In | D8: Preloved 2020
A9: 9 | B9: Nevia Portable Warmer | C9: In
A10: 10 | B10: Bebetons Neo v2 | C10: In | D10: Preloved maret 2023 | E10: Back 12 maret
A11: 11 | B11: Momabae omni 1 | C11: Out | D11: Preloved 2024 | E11: Back 12 maret
A12: 12 | B12: Momabae omni 2 | C12: Out | D12: Preloved 2024
A13: 13 | B13: Mom Uung Handsfree | C13: In
A14: 14 | B14: Spectra 9+ | C14: Out | D14: Sticker no 14&2 | E14: Preloved 2021 | F14: 46096
A15: 15 | B15: Spectra H1 Lite | C15: Out | D15: Preloved 2023
A16: 16
A17: 17 | B17: Nevia Portable Warmer 2 | C17: Out
A18: 18 | B18: Spectra Dual S | C18: Out | D18: Preloved 2020 | E18: Back 11 maret
A19: 19 | B19: Spectra 9+ 2 | C19: Out | D19: Karet belakangnya hilang 1 | E19: Preloved 2021
A20: 20
A21: 21 | B21: Momabae Omni 3 | C21: Out | D21: Preloved 2024 | E21: Back 8 maret
A22: 22 | B22: Momabae Omni 4 | C22: Out | D22: Preloved 2024 | E22: Back 12 maret
A23: 23 | B23: Momabae Omni 5 | C23: Out | D23: Preloved 2024 | E23: Back 9 maret
A24: 24 | B24: Momabae Omni 6 | C24: Out | D24: Preloved 2024 | E24: Back 2 maret
A25: 25 | B25: Medela Swing Maxi hf | C25: Out | D25: Preloved maret 2025 | E25: 46079
A26: 26 | B26: Momcozy v1 pro | C26: Out | D26: Preloved 2025 | E26: Back 7 maret
A27: 27 | B27: Medela swing maxi double | C27: In | D27: Preloved des 2025
A28: 28 | B28: Opia diamond | C28: Out | D28: Preloved 2023 | E28: Back 28 maret
A29: 29 | B29: Spectra dual compact 3 | C29: Out | D29: Preloved juni 2024
A30: 30 | B30: Momcozy v1 pro | C30: Out | D30: New 2026 | E30: Back 5 maret
A31: 31 | B31: Momabae Omni S+ 1 | C31: In | D31: New 2026
A32: 32 | B32: Momabae Omni S+ 2 | C32: Out | D32: New 2026
A33: 33 | B33: Momcozy V2 Pro | C33: Out | D33: New 2026
A34: 34 | B34: Momcozy M9 2 | C34: Out | D34: New 2026
A35: 35 Momcozy V2 Pro | B35: Momcozy M9 | C35: Out | D35: New 2026
A36: 36 | B36: Momcozy v2 pro 2 | C36: Out | D36: Preloved 2026
A37: 37 | B37: Mooimom m3 pro 1 | C37: Out | D37: New 2026
A38: 38 | B38: Mooimom m3 pro 2 | C38: Out | D38: New 2026
A39: 39 | B39: Mooimom x1 1 | C39: Out | D39: Preloved 2026
A40: 40 | B40: Momabae compact s+ | C40: Out
...

Sheet modal
A1: UNIT | B1: MODAL | C1: Harga jual | D1: on shopee | F1: Hasil akhir | K1: 1 month
A2: Spectra Dual Compact 1 | B2: 1500000 | C2: 80000 | D2: 100000 | E2: =(D2-C2)/C2 -> 0.25 | F2: =(D2-9.5%*D2)-1250 -> 89250 | I2: Spectra Dual Compact 1 | J2: 2600000 | K2: =J2*10% -> 260000 | L2: =(K2/2)+20000 -> 150000 | M2: =(K2/4)+20000 -> 85000
A3: Spectra Dual Compact 2 | B3: 1700000 | C3: 140000 | D3: 175000 | E3: =(D3-C3)/C3 -> 0.25 | F3: =(D3-9.5%*D3)-1250 -> 157125 | G3: =((Pemasukan!G3)-(B2+B3+B4)) -> 4313000 | I3: Mom Uung Corong | J3: 600000 | K3: =J3*10% -> 60000 | L3: =(K3/2)+20000 -> 50000 | M3: =(K3/4)+20000 -> 35000
A4: Spectra dual compact 3 | B4: 1650000 | C4: 250000 | D4: 310000 | E4: =(D4-C4)/C4 -> 0.24 | F4: =(D4-9.5%*D4)-1250 -> 279300 | I4: Gabag Maximo 1 | J4: 800000 | K4: =J4*10% -> 80000 | L4: =(K4/2)+20000 -> 60000 | M4: =(K4/4)+20000 -> 40000
A5: Mom Uung Corong | B5: 278000 | C5: 50000 | D5: 65000 | E5: =(D5-C5)/C5 -> 0.3 | F5: =(D5-9.5%*D5)-1250 -> 57575 | I5: Spectra S1+ | J5: 3115000 | K5: =J5*10% -> 311500 | L5: =(K5/2)+20000 -> 175750 | M5: =(K5/4)+20000 -> 97875
C6: 75000 | D6: 95000 | E6: =(D6-C6)/C6 -> 0.26666667 | F6: =(D6-9.5%*D6)-1250 -> 84725 | I6: Gabag Imax Pro Cup LED | K6: =J6*10% -> 0 | L6: =(K6/2)+20000 -> 20000 | M6: =(K6/4)+20000 -> 20000
C7: 125000 | D7: 160000 | E7: =(D7-C7)/C7 -> 0.28 | F7: =(D7-9.5%*D7)-1250 -> 143550 | I7: Malish Flexigo | K7: =J7*10% -> 0 | L7: =(K7/2)+20000 -> 20000 | M7: =(K7/4)+20000 -> 20000
A8: Gabag Maximo 1 | B8: 500000 | C8: 60000 | D8: 75000 | E8: =(D8-C8)/C8 -> 0.25 | F8: =(D8-9.5%*D8)-1250 -> 66625 | G8: =((Pemasukan!G4)-(B8+B9+B10)) -> 1020000 | I8: Nevia Portable Warmer 1 | K8: =J8*10% -> 0 | L8: =(K8/2)+20000 -> 20000 | M8: =(K8/4)+20000 -> 20000
A9: Gabag Maximo 2 | B9: 800000 | C9: 100000 | D9: 125000 | E9: =(D9-C9)/C9 -> 0.25 | F9: =(D9-9.5%*D9)-1250 -> 111875 | I9: Bebetons Neo v2 | K9: =J9*10% -> 0 | L9: =(K9/2)+20000 -> 20000 | M9: =(K9/4)+20000 -> 20000
A10: Gabag Maximo 3 & 4 | B10: 1100000 | C10: 170000 | D10: 215000 | E10: =(D10-C10)/C10 -> 0.26470588 | F10: =(D10-9.5%*D10)-1250 -> 193325 | I10: Momabae omni 1 & 2 | J10: 1100000 | K10: =J10*10% -> 110000 | L10: =(K10/2)+20000 -> 75000 | M10: =(K10/4)+20000 -> 47500
A11: Spectra S1+ | B11: 1400000 | C11: 100000 | D11: 125000 | E11: =(D11-C11)/C11 -> 0.25 | F11: =(D11-9.5%*D11)-1250 -> 111875 | I11: Mom Uung Handsfree | J11: 700000 | K11: =J11*10% -> 70000 | L11: =(K11/2)+20000 -> 55000 | M11: =(K11/4)+20000 -> 37500
C12: 180000 | D12: 225000 | E12: =(D12-C12)/C12 -> 0.25 | F12: =(D12-9.5%*D12)-1250 -> 202375 | I12: Spectra 9+ 1 | J12: 2100000 | K12: =J12*10% -> 210000 | L12: =(K12/2)+20000 -> 125000 | M12: =(K12/4)+20000 -> 72500
C13: 310000 | D13: 390000 | E13: =(D13-C13)/C13 -> 0.25806452 | F13: =(D13-9.5%*D13)-1250 -> 351700 | I13: Spectra H1 Lite | J13: 1500000 | K13: =J13*10% -> 150000 | L13: =(K13/2)+20000 -> 95000 | M13: =(K13/4)+20000 -> 57500
A14: Gabag Imax Pro Cup LED | B14: 562000 | C14: 60000 | D14: 75000 | E14: =(D14-C14)/C14 -> 0.25 | F14: =(D14-9.5%*D14)-1250 -> 66625 | G14: =((Pemasukan!G10)-(B14+B15+B16)) -> -62000 | I14: Momabae Compact S+ 1 | J14: 1400000 | K14: =J14*10% -> 140000 | L14: =(K14/2)+20000 -> 90000 | M14: =(K14/4)+20000 -> 55000
C15: 100000 | D15: 125000 | E15: =(D15-C15)/C15 -> 0.25 | F15: =(D15-9.5%*D15)-1250 -> 111875 | I15: Spectra Dual S | J15: 3000000 | K15: =J15*10% -> 300000 | L15: =(K15/2)+20000 -> 170000 | M15: =(K15/4)+20000 -> 95000
C16: 170000 | D16: 215000 | E16: =(D16-C16)/C16 -> 0.26470588 | F16: =(D16-9.5%*D16)-1250 -> 193325 | I16: Medela swing maxi hf | J16: 5000000 | K16: =J16*10% -> 500000 | L16: =(K16/2)+20000 -> 270000 | M16: =(K16/4)+20000 -> 145000
A17: Malish Flexigo | B17: 160000 | C17: 40000 | D17: 50000 | E17: =(D17-C17)/C17 -> 0.25 | F17: =(D17-9.5%*D17)-1250 -> 44000 | I17: Momcozy v1 pro | J17: 3200000 | K17: =J17*10% -> 320000 | L17: =(K17/2)+20000 -> 180000 | M17: =(K17/4)+20000 -> 100000
C18: 60000 | D18: 70000 | E18: =(D18-C18)/C18 -> 0.16666667 | F18: =(D18-9.5%*D18)-1250 -> 62100 | I18: Medela swing maxi double | J18: 5000000 | K18: =J18*10% -> 500000 | L18: =(K18/2)+20000 -> 270000 | M18: =(K18/4)+20000 -> 145000
C19: 100000 | D19: 115000 | E19: =(D19-C19)/C19 -> 0.15 | F19: =(D19-9.5%*D19)-1250 -> 102825 | I19: Opia diamond | J19: 2700000 | K19: =J19*10% -> 270000 | L19: =(K19/2)+20000 -> 155000 | M19: =(K19/4)+20000 -> 87500
A20: Nevia Portable Warmer 1 | B20: 600000 | C20: 50000 | D20: 65000 | E20: =(D20-C20)/C20 -> 0.3 | F20: =(D20-9.5%*D20)-1250 -> 57575 | G20: =((Pemasukan!G6+Pemasukan!G7)-(B20+B21)) -> 40000 | I20: Momcozy m9 | J20: 2400000 | K20: =J20*10% -> 240000 | L20: =(K20/2)+20000 -> 140000 | M20: =(K20/4)+20000 -> 80000
A21: Nevia Portable Warmer 2 | B21: 400000 | C21: 70000 | D21: 90000 | E21: =(D21-C21)/C21 -> 0.28571429 | F21: =(D21-9.5%*D21)-1250 -> 80200 | I21: Momabae Omni S+ | J21: 1300000 | K21: =J21*10% -> 130000 | L21: =(K21/2)+20000 -> 85000 | M21: =(K21/4)+20000 -> 52500
C22: 115000 | D22: 145000 | E22: =(D22-C22)/C22 -> 0.26086957 | F22: =(D22-9.5%*D22)-1250 -> 129975 | I22: Momcozy V2 Pro | J22: 3100000 | K22: =J22*10% -> 310000 | L22: =(K22/2)+20000 -> 175000 | M22: =(K22/4)+20000 -> 97500
C23: 60000 | D23: 75000 | E23: =(D23-C23)/C23 -> 0.25 | F23: =(D23-9.5%*D23)-1250 -> 66625
C24: 80000 | D24: 100000 | E24: =(D24-C24)/C24 -> 0.25 | F24: =(D24-9.5%*D24)-1250 -> 89250
C25: 125000 | D25: 155000 | E25: =(D25-C25)/C25 -> 0.24 | F25: =(D25-9.5%*D25)-1250 -> 139025
A26: Bebetons Neo v2 | B26: 310000 | C26: 50000 | D26: 65000 | E26: =(D26-C26)/C26 -> 0.3 | F26: =(D26-9.5%*D26)-1250 -> 57575 | G26: =((Pemasukan!G15)-(B26+B27+B28)) -> 10000
C27: 75000 | D27: 95000 | E27: =(D27-C27)/C27 -> 0.26666667 | F27: =(D27-9.5%*D27)-1250 -> 84725
C28: 125000 | D28: 160000 | E28: =(D28-C28)/C28 -> 0.28 | F28: =(D28-9.5%*D28)-1250 -> 143550
A29: Momabae omni 1 & 2 | B29: 1250000 | C29: 60000 | D29: 75000 | E29: =(D29-C29)/C29 -> 0.25 | F29: =(D29-9.5%*D29)-1250 -> 66625 | G29: =((Pemasukan!G9)-(B29+B30+B31)) -> 6376500
A30: Momabae omni 3 & 4 | B30: 1400000 | C30: 100000 | D30: 125000 | E30: =(D30-C30)/C30 -> 0.25 | F30: =(D30-9.5%*D30)-1250 -> 111875
A31: Momabae omni 5 & 6 | B31: 1200000 | C31: 170000 | D31: 215000 | E31: =(D31-C31)/C31 -> 0.26470588 | F31: =(D31-9.5%*D31)-1250 -> 193325
A32: Mom Uung Handsfree | B32: 450000 | C32: 60000 | D32: 75000 | E32: =(D32-C32)/C32 -> 0.25 | F32: =(D32-9.5%*D32)-1250 -> 66625 | G32: =(Pemasukan!G14- B32) -> 905000
C33: 100000 | D33: 125000 | E33: =(D33-C33)/C33 -> 0.25 | F33: =(D33-9.5%*D33)-1250 -> 111875
C34: 170000 | D34: 215000 | E34: =(D34-C34)/C34 -> 0.26470588 | F34: =(D34-9.5%*D34)-1250 -> 193325
A35: Spectra 9+ 1 | B35: 650000 | C35: 75000 | D35: 95000 | E35: =(D35-C35)/C35 -> 0.26666667 | F35: =(D35-9.5%*D35)-1250 -> 84725 | G35: =(Pemasukan!G12-(B35+B36)) -> 3185000
A36: Spectra 9+ 2 | B36: 650000 | C36: 130000 | D36: 165000 | E36: =(D36-C36)/C36 -> 0.26923077 | F36: =(D36-9.5%*D36)-1250 -> 148075
C37: 230000 | D37: 290000 | E37: =(D37-C37)/C37 -> 0.26086957 | F37: =(D37-9.5%*D37)-1250 -> 261200
A38: Spectra H1 Lite | B38: 850000 | C38: 70000 | D38: 90000 | E38: =(D38-C38)/C38 -> 0.28571429 | F38: =(D38-9.5%*D38)-1250 -> 80200 | G38: =((Pemasukan!G13)-(B38+B39+B40)) -> -360000
C39: 120000 | D39: 150000 | E39: =(D39-C39)/C39 -> 0.25 | F39: =(D39-9.5%*D39)-1250 -> 134500
C40: 210000 | D40: 265000 | E40: =(D40-C40)/C40 -> 0.26190476 | F40: =(D40-9.5%*D40)-1250 -> 238575
...

Sheet Pemasukan
A1: Pemasukan
A2: Tanggal | B2: Keterangan | C2: Durasi | D2: Jumlah | E2: TOTAL PEMASUKAN | F2: jenis | G2: penghasilan
A3: 45585 | B3: Spectra dual compact | C3: 1 minggu | D3: 80000 | E3: =D12+D24+D37+D54+D79+D100+D128+D154+D190+D223+D260+D285+D315+D344+D389+D443+D476 -> 58245500 | F3: Dual compact | G3: =sumif(B3:B517,"spectra dual compact",D3:D637) -> 9163000
A4: 45597 | B4: Spectra dual compact | C4: 1 minggu | D4: 80000 | F4: gabag maximo | G4: =sumif(B3:B517,"gabag maximo",D3:D4537) -> 3420000
A5: 45609 | B5: gabag maximo | C5: 1 bulan | D5: 170000 | F5: spectra s1+ | G5: =sumif(B3:B517,"spectra s1+",D3:D537) -> 3580000
A6: 45609 | B6: gabag maximo | C6: 1 minggu | D6: 60000 | F6: warmer | G6: =sumif(B3:B517,"Nevia portable warmer",D3:D517) -> 510000
A7: 45614 | B7: gabag maximo | C7: 1 bulan | D7: 170000 | F7: warmer + adptr | G7: =sumif(B3:B517,"nevia portable warmer + adaptor",D3:D517) -> 530000
A8: 45626 | B8: Spectra dual compact | C8: 2 minggu | D8: 140000 | F8: Mom uung p | G8: =sumif(B3:B517,"mom uung portable",D3:D517) -> 930000
A9: 45627 | B9: spectra s1+ | C9: 1 bulan | D9: 310000 | F9: Momabae omni | G9: =sumif(B3:B517,"momabae omni",D3:D517) -> 10226500
A10: 45638 | B10: Spectra dual compact | C10: 2 minggu | D10: 140000 | F10: gabag imax | G10: =sumif(B3:B517,"gabag imax pro cup led",D3:D517) -> 500000
A11: 45654 | B11: Spectra dual compact | C11: 1 bulan | D11: 250000 | F11: compact s+ | G11: =sumif(B3:B517,"momabae compact s+",D3:D517) -> 2695000
B12: TOTAL | D12: =SUM(D3:D11) -> 1400000 | F12: spectra 9+ | G12: =sumif(B3:B517,"spectra 9+",D3:D517) -> 4485000
F13: h1 lite | G13: =sumif(B3:B517,"spectra h1 lite",D3:D517) -> 490000
A14: 45659 | B14: spectra s1+ | C14: 2 bulan free 2 minggu | D14: 620000 | F14: mom uung hf | G14: =sumif(B3:B517,"mom uung handsfree",D3:D517) -> 1355000
A15: 45680 | B15: gabag maximo | C15: 1 minggu | D15: 60000 | F15: bebetons v2 | G15: =sumif(B3:B517,"bebetons neo v2",D3:D517) -> 320000
A16: 45687 | B16: Spectra dual compact | C16: 1 bulan | D16: 250000 | F16: dual s | G16: =sumif(B3:B517,"spectra dual s",D3:D517) -> 2781000
A17: 45691 | B17: Nevia portable warmer | C17: 1 minggu | D17: 70000 | F17: medela sm hf | G17: =sumif(B3:B517,"medela swing maxi hf",D3:D517) -> 2220000
A18: 45692 | B18: Mom Uung portable | C18: 1 minggu | D18: 55000 | F18: momcozy v1 | G18: =sumif(B3:B517,"momcozy v1 pro",D3:D517) -> 5380000
A19: 45692 | B19: Bebetons neo v2 | C19: 1 minggu | D19: 70000 | F19: Opia | G19: =sumif(B3:B517,"opia diamond",D3:D517) -> 1240000
A20: 45701 | B20: Nevia portable warmer + adaptor | C20: 1 minggu | D20: 80000 | F20: Medela sm double | G20: =sumif(B3:B517,"medela swing maxi double",D3:D517) -> 1000000
A21: 45705 | B21: Spectra dual compact | C21: 1 minggu | D21: 80000 | F21: Momcozy m9 | G21: =sumif(B4:B518,"Momcozy m9",D4:D518) -> 1320000
A22: 45714 | B22: Spectra dual compact | C22: 1 minggu | D22: 80000 | F22: Momcozy v2 | G22: =sumif(B5:B519,"Momcozy v2 pro",D5:D519) -> 1950000
A23: 45716 | B23: Gabag maximo | C23: 1 minggu | D23: 60000 | F23: Omni s+ | G23: =sumif(B6:B520,"Momabae Omni S+",D6:D520) -> 1060000
B24: TOTAL | D24: =SUM(D14:D23) -> 1425000 | F24: Mooimom m3 | G24: =sumif(B7:B521,"Mooimom m3 pro",D7:D521) -> 910000
F25: Mooimom x1 | G25: =sumif(B8:B522,"Mooimom x1",D8:D522) -> 490000
A26: 45719 | B26: Spectra dual compact | C26: 1 bulan | D26: 250000 | F26: medela hf cup | G26: =sumif(B9:B523,"Medela Handsfree cup",D9:D523) -> 310000
A27: 45722 | B27: Spectra Dual Compact | C27: 2 minggu | D27: 140000
A28: 45731 | B28: Momabae omni | C28: 1 minggu | D28: 60000
A29: 45731 | B29: Spectra s1+ | C29: 1 bulan | D29: 310000
A30: 45732 | B30: Momabae omni | C30: 1 minggu | D30: 60000
A31: 45732 | B31: Momabae omni | C31: 1 minggu | D31: 60000
A32: 45733 | B32: Gabag maximo | C32: 2 minggu | D32: 100000
A33: 45738 | B33: Gabag imax pro cup led | C33: 1 bulan | D33: 170000
A34: 45740 | B34: Momabae omni | C34: 1 bulan | D34: 170000
A35: 45742 | B35: Spectra Dual Compact | C35: 1 bulan | D35: 250000
A36: 45742 | B36: nevia portable warmer | C36: 1 minggu | D36: 60000
B37: TOTAL | D37: =SUM(D26:D36) -> 1630000
A39: 45757 | B39: Nevia portable warmer + adaptor | C39: 1 bulan | D39: 125000
A40: 45763 | B40: Spectra Dual Compact | C40: 1 minggu | D40: 80000
A41: 45763 | B41: Spectra s1+ | C41: 1 bulan free 1 minggu | D41: 310000
...

Sheet Pengeluaran
A1: Pengeluaran
A2: Tanggal | B2: Keterangan | C2: Modal | D2: Pengeluaran
A3: 45658 | B3: spectra dc | C3: 1700000
A4: 45689 | B4: momabae omni | C4: 1250000
A5: 45690 | B5: beli sparepart cadangan | D5: 110000
B6: Iklan Shopee | D6: 110000
A7: 45690 | B7: Botol pumping | D7: 95000
B8: Sparepart pompa | D8: 153000
B9: kantong asip kolibri beli di imbex | D9: 100000
A10: 45709 | B10: Kasip blibli | D10: 152500
A11: 45714 | B11: Iklan shopee | D11: 26100
A12: 45719 | B12: Sparepart pompa | D12: 57500
A13: 45730 | B13: Iklan shopee | D13: 55500
A14: 45732 | B14: Admin bank | D14: 10000
A15: 45756 | B15: Sticker dan freebies | D15: 76000
A16: 45761 | B16: Iklan shopee | D16: 55500
A17: 45764 | B17: Mom uung handsfree | C17: 450000
A18: 45765 | B18: Sparepart pompa | D18: 426350
B19: Gabag maximo 2pcs | C19: 1100000
A20: 45772 | B20: Sparepart pompa | C20: 134000
B21: Spectra h1 lite | C21: 850000
B22: Momabae compact s+ | C22: 750000
B23: Spectra 9+ | C23: 650000
A24: 45780 | B24: Ongkir valve bandung | D24: 23500
A25: 45782 | B25: Sparepart momabae compact | D25: 57000
A26: 45783 | B26: Iklan shopee | D26: 27750
A27: 45786 | B27: Iklan shopee | D27: 27750
A28: 45786 | B28: hasil sewa mami | D28: 50000
A29: 45794 | B29: Iklan shopee | D29: 55500
A30: 45799 | B30: Sparepart pompa | D30: 260000
A31: 45805 | B31: Ongkir service | D31: 86000
A32: 45819 | B32: Spectra dual s | C32: 1500000
A33: 45819 | B33: Sparepart spectra | D33: 300000
A34: 45821 | B34: Iklan shopee | D34: 27750
A35: 45825 | B35: Sparepart pompa | D35: 53000
A36: 45827 | B36: Service gabag | D36: 200000
A37: 45839 | B37: Spectra 9+ | C37: 940000
A38: 45839 | B38: Momabae compact s+ | C38: 550000
A39: 45842 | B39: Momabae omni | C39: 1400000
A40: 45851 | B40: Momabae omni | C40: 1200000
...

Sheet Pumps to buy
A1: No. | B1: Merk | C1: Unit | D1: Official Price | E1: Bought | F1: Not Buying
B2: Momabae | F2: Circlo S+ | G2: 745000
C3: Compact S+ | D3: 1390000 | E3: =D3*2 -> 2780000
C4: Diamond | D4: 670000
C5: Eclat N+ | D5: 1430000
C6: Omni | D6: 1080000 | E6: =D6*6 -> 6480000
B7: Mutter | C7: Gold Links | D7: 1540000
C8: Krystal HK | D8: 1550000
C9: Topaz Go | D9: 690000
C10: Topaz | D10: 915000
C11: Pearl | D11: 1250000
B12: Mooimom | C12: M3 pro airflow | D12: 1000000 | E12: =D12*2 -> 2000000
F13: M2 | G13: 600000
C14: X1 | D14: 1575000 | E14: =D14*2 -> 3150000
F15: B9 Pro | G15: 800000
B16: Spectra | C16: H1 Lite | D16: 1600000 | E16: 1600000
C17: Dual Compact | D17: 2500000 | E17: =D17*3 -> 7500000
F18: QR | G18: 1300000
C19: 9+ | D19: 2350000 | E19: =D19*2 -> 4700000
C20: Dual S | D20: 3480000 | E20: 3480000
C21: S1 Pro | D21: 3530000
C22: S1+ | D22: 3000000 | E22: 3000000
B23: Opia | C23: Diamond | D23: 2640000 | E23: 2640000
C24: Pearl | D24: 1795000
C25: Topaz | D25: 1155000
B26: Imani | C26: I2+ | D26: 1300000
B27: Haenim | C27: 7V Pro | D27: 2390000
C28: 7X | D28: 2990000
C29: 7S | D29: 1380000
F30: 7A Lite | G30: 1890000
B31: Youha | C31: The Ins Gen 3 | D31: 990000
C32: The Ins Gen 2 | D32: 1160000
F33: Hola | G33: 640000
C34: The One | D34: 1970000
C35: Smart | D35: 980000
F36: AIO | G36: 590000
C37: Duo | D37: 930000
B38: Elmom | C38: M2 Compact | D38: 1300000
C39: M1 | D39: 900000
B40: Horigen | F40: Polaris | G40: 1050000
...
